<robot
  name="Assembly">
  <link
    name="base_link">
    <inertial>
      <origin
        xyz="0.086354 0.066639 0.1558"
        rpy="0 0 0" />
      <mass
        value="0.81514" />
      <inertia
        ixx="0.0010164"
        ixy="-2.6835E-14"
        ixz="0.00020825"
        iyy="0.0014122"
        iyz="5.874E-14"
        izz="0.00076199" />
    </inertial>
    <visual>
      <origin
        xyz="0 0 0"
        rpy="0 0 0" />
      <geometry>
        <mesh
          filename="package://Assembly/meshes/base_link.STL" />
      </geometry>
      <material
        name="">
        <color
          rgba="0 0 1 1" />
      </material>
    </visual>
    <collision>
      <origin
        xyz="0 0 0"
        rpy="0 0 0" />
      <geometry>
        <mesh
          filename="package://Assembly/meshes/base_link.STL" />
      </geometry>
    </collision>
  </link>
  <link
    name="link_1">
    <inertial>
      <origin
        xyz="0.0025832 -2.2099E-05 0.031738"
        rpy="0 0 0" />
      <mass
        value="0.85108" />
      <inertia
        ixx="0.00043864"
        ixy="-2.6609E-07"
        ixz="-7.5681E-06"
        iyy="0.0011002"
        iyz="5.1488E-08"
        izz="0.0010411" />
    </inertial>
    <visual>
      <origin
        xyz="0 0 0"
        rpy="0 0 0" />
      <geometry>
        <mesh
          filename="package://Assembly/meshes/link_1.STL" />
      </geometry>
      <material
        name="">
        <color
          rgba="0 1 0 1" />
      </material>
    </visual>
    <collision>
      <origin
        xyz="0 0 0"
        rpy="0 0 0" />
      <geometry>
        <mesh
          filename="package://Assembly/meshes/link_1.STL" />
      </geometry>
    </collision>
  </link>
  <joint
    name="joint_1"
    type="revolute">
    <origin
      xyz="0.091831 -0.027715 0.066639"
      rpy="1.5708 0 0" />
    <parent
      link="base_link" />
    <child
      link="link_1" />
    <axis
      xyz="0 0 -1" />
    <limit
      upper="1.97"
      lower="-1.97"
      effort="0"
      velocity="0" />
  </joint>
  <link
    name="link_2">
    <inertial>
      <origin
        xyz="0.090332 8.3782E-06 -0.00037683"
        rpy="0 0 0" />
      <mass
        value="0.95707" />
      <inertia
        ixx="0.00086793"
        ixy="-2.4885E-07"
        ixz="9.1493E-05"
        iyy="0.0019572"
        iyz="1.0238E-08"
        izz="0.0015294" />
    </inertial>
    <visual>
      <origin
        xyz="0 0 0"
        rpy="0 0 0" />
      <geometry>
        <mesh
          filename="package://Assembly/meshes/link_2.STL" />
      </geometry>
      <material
        name="">
        <color
          rgba="1 1 0 1" />
      </material>
    </visual>
    <collision>
      <origin
        xyz="0 0 0"
        rpy="0 0 0" />
      <geometry>
        <mesh
          filename="package://Assembly/meshes/link_2.STL" />
      </geometry>
    </collision>
  </link>
  <joint
    name="joint_2"
    type="revolute">
    <origin
      xyz="0 0 0.029"
      rpy="3.1416 1.5708 0" />
    <parent
      link="link_1" />
    <child
      link="link_2" />
    <axis
      xyz="0 0 1" />
    <limit
      upper="1.97"
      lower="-1.97"
      effort="0"
      velocity="0" />
  </joint>
  <link
    name="link_3">
    <inertial>
      <origin
        xyz="-0.043217 0.02917 -0.046441"
        rpy="0 0 0" />
      <mass
        value="1.1818" />
      <inertia
        ixx="0.005343"
        ixy="-0.00039317"
        ixz="-0.0014108"
        iyy="0.0055981"
        iyz="0.00094945"
        izz="0.0034336" />
    </inertial>
    <visual>
      <origin
        xyz="0 0 0"
        rpy="0 0 0" />
      <geometry>
        <mesh
          filename="package://Assembly/meshes/link_3.STL" />
      </geometry>
      <material
        name="">
        <color
          rgba="0.9098 0.44314 0.031373 1" />
      </material>
    </visual>
    <collision>
      <origin
        xyz="0 0 0"
        rpy="0 0 0" />
      <geometry>
        <mesh
          filename="package://Assembly/meshes/link_3.STL" />
      </geometry>
    </collision>
  </link>
  <joint
    name="joint_3"
    type="revolute">
    <origin
      xyz="0.079 0 0"
      rpy="-1.5708 -1.0472 1.5708" />
    <parent
      link="link_2" />
    <child
      link="link_3" />
    <axis
      xyz="0 0 -1" />
    <limit
      upper="1.97"
      lower="-1.97"
      effort="0"
      velocity="0" />
  </joint>
  <link
    name="link_4">
    <inertial>
      <origin
        xyz="-1.0568E-07 0.14408 0.002096"
        rpy="0 0 0" />
      <mass
        value="0.22206" />
      <inertia
        ixx="0.0018982"
        ixy="3.2002E-09"
        ixz="-1.6172E-09"
        iyy="0.00018215"
        iyz="-8.3062E-05"
        izz="0.0018567" />
    </inertial>
    <visual>
      <origin
        xyz="0 0 0"
        rpy="0 0 0" />
      <geometry>
        <mesh
          filename="package://Assembly/meshes/link_4.STL" />
      </geometry>
      <material
        name="">
        <color
          rgba="1 0 0 1" />
      </material>
    </visual>
    <collision>
      <origin
        xyz="0 0 0"
        rpy="0 0 0" />
      <geometry>
        <mesh
          filename="package://Assembly/meshes/link_4.STL" />
      </geometry>
    </collision>
  </link>
  <joint
    name="joint_4"
    type="revolute">
    <origin
      xyz="0.00077942 -0.00045 -0.2104"
      rpy="-1.5708 0 2.618" />
    <parent
      link="link_3" />
    <child
      link="link_4" />
    <axis
      xyz="0 0 -1" />
    <limit
      upper="1.97"
      lower="-1.97"
      effort="0"
      velocity="0" />
  </joint>
</robot>
